Workbook

Sheet FD Raw Data
A1: Sales_Order # | B1: Date | C1: Day | D1: Month | E1: Year | F1: Customer_Age | G1: Age_Group | H1: Customer_Gender | I1: Country | J1: State | K1: Product_Category | L1: Sub_Category | M1: Product_Description | N1: Order_Quantity | O1: Unit_Cost | P1: Unit_Price | Q1: Profit | R1: Cost | S1: Revenue
A2: 000261695 | B2: 44531 | C2: 1 | D2: December | E2: 2021 | F2: 39 | G2: Adults (35-64) | H2: F | I2: United States | J2: California | K2: Bikes | L2: Mountain Bikes | M2: Mountain-200 Black, 46 | N2: 4 | O2: 1252 | P2: 2295 | Q2: 4172 | R2: =N2*O2 -> 5008 | S2: =N2*P2 -> 9180
A3: 000261695 | B3: 44531 | C3: 1 | D3: December | E3: 2021 | F3: 44 | G3: Adults (35-64) | H3: M | I3: United Kingdom | J3: England | K3: Bikes | L3: Mountain Bikes | M3: Mountain-200 Silver, 42 | N3: 1 | O3: 1266 | P3: 2320 | Q3: 1054 | R3: =N3*O3 -> 1266 | S3: =N3*P3 -> 2320
A4: 000261697 | B4: 44532 | C4: 2 | D4: December | E4: 2021 | F4: 37 | G4: Adults (35-64) | H4: M | I4: United States | J4: California | K4: Bikes | L4: Mountain Bikes | M4: Mountain-400-W Silver, 46 | N4: 2 | O4: 420 | P4: 769 | Q4: 698 | R4: =N4*O4 -> 840 | S4: =N4*P4 -> 1538
A5: 000261698 | B5: 44532 | C5: 2 | D5: December | E5: 2021 | F5: 31 | G5: Young Adults (25-34) | H5: F | I5: Australia | J5: New South Wales | K5: Bikes | L5: Mountain Bikes | M5: Mountain-400-W Silver, 42 | N5: 1 | O5: 420 | P5: 769 | Q5: 349 | R5: =N5*O5 -> 420 | S5: =N5*P5 -> 769
A6: 000261699 | B6: 44533 | C6: 3 | D6: December | E6: 2021 | F6: 37 | G6: Adults (35-64) | H6: F | I6: United States | J6: California | K6: Bikes | L6: Mountain Bikes | M6: Mountain-200 Black, 46 | N6: 2 | O6: 0 | P6: 2295 | Q6: 2086 | R6: =N6*O6 -> 0 | S6: =N6*P6 -> 4590
A7: 000261700 | B7: 44533 | C7: 3 | D7: December | E7: 2021 | F7: 24 | G7: Youth (<25) | H7: F | I7: United Kingdom | J7: England | K7: Bikes | L7: Mountain Bikes | M7: Mountain-200 Black, 38 | N7: 1 | O7: 1252 | P7: 2295 | Q7: 1043 | R7: =N7*O7 -> 1252 | S7: =N7*P7 -> 2295
A8: 000261701 | B8: 44533 | C8: 3 | D8: December | E8: 2021 | F8: 37 | G8: Adults (35-64) | H8: M | I8: United States | J8: Washington | K8: Bikes | L8: Mountain Bikes | M8: Mountain-200 Black, 46 | N8: 1 | O8: 1252 | P8: 2295 | Q8: 1043 | R8: =N8*O8 -> 1252 | S8: =N8*P8 -> 2295
A9: 000261702 | B9: 44534 | C9: 4 | D9: December | E9: 2021 | F9: 31 | G9: Young Adults (25-34) | H9: F | I9: Australia | J9: New South Wales | K9: Bikes | L9: Mountain Bikes | M9: Mountain-400-W Silver, 42 | N9: 4 | O9: 420 | P9: 0 | Q9: 1396 | R9: =N9*O9 -> 1680 | S9: =N9*P9 -> 0
A10: 000261703 | B10: 44535 | C10: 5 | D10: December | E10: 2021 | F10: 39 | G10: Adults (35-64) | H10: F | I10: United States | J10: California | K10: Bikes | L10: Mountain Bikes | M10: Mountain-200 Black, 46 | N10: 4 | O10: 1252 | P10: 2295 | Q10: 4172 | R10: =N10*O10 -> 5008 | S10: =N10*P10 -> 9180
A11: 000261704 | B11: 44535 | D11: December | E11: 2021 | F11: 42 | G11: Adults (35-64) | H11: M | I11: Germany | J11: Nordrhein-Westfalen | K11: Bikes | L11: Mountain Bikes | M11: Mountain-200 Black, 38 | N11: 4 | O11: 1252 | P11: 2295 | Q11: 4172 | R11: =N11*O11 -> 5008 | S11: =N11*P11 -> 9180
A12: 000261705 | B12: 44535 | C12: 5 | D12: December | E12: 2021 | F12: 35 | G12: Adults (35-64) | H12: F | I12: Australia | J12: Queensland | K12: Bikes | L12: Mountain Bikes | M12: Mountain-200 Silver, 38 | N12: 1 | O12: 1266 | P12: 2320 | Q12: 1054 | R12: =N12*O12 -> 1266 | S12: =N12*P12 -> 2320
A13: 000261706 | B13: 44535 | C13: 5 | D13: December | E13: 2021 | F13: 37 | G13: Adults (35-64) | H13: F | I13: United States | J13: California | K13: Bikes | L13: Mountain Bikes | M13: Mountain-200 Black, 46 | N13: 1 | O13: 1252 | P13: 2295 | Q13: 1043 | R13: =N13*O13 -> 1252 | S13: =N13*P13 -> 2295
A14: 000261707 | B14: 44536 | C14: 6 | D14: December | E14: 2021 | F14: 23 | G14: Youth (<25) | H14: M | I14: United Kingdom | J14: England | K14: Bikes | L14: Mountain Bikes | M14: Mountain-400-W Silver, 46 | N14: 3 | O14: 420 | P14: 769 | Q14: 1047 | R14: =N14*O14 -> 1260 | S14: =N14*P14 -> 2307
A15: 000261708 | B15: 44536 | C15: 6 | D15: December | E15: 2021 | F15: 27 | G15: Young Adults (25-34) | H15: M | I15: Canada | J15: British Columbia | K15: Bikes | L15: Mountain Bikes | M15: Mountain-200 Black, 46 | N15: 1 | O15: 1252 | P15: 2295 | Q15: 1043 | R15: =N15*O15 -> 1252 | S15: =N15*P15 -> 2295
A16: 000261709 | B16: 44536 | C16: 6 | D16: December | E16: 2021 | F16: 36 | H16: M | I16: Australia | J16: New South Wales | K16: Bikes | L16: Mountain Bikes | M16: Mountain-200 Black, 42 | N16: 1 | O16: 1252 | P16: 2295 | Q16: 1043 | R16: =N16*O16 -> 1252 | S16: =N16*P16 -> 2295
A17: 000261710 | B17: 44536 | C17: 6 | D17: December | E17: 2021 | F17: 47 | G17: Adults (35-64) | H17: M | I17: United Kingdom | J17: England | K17: Bikes | L17: Mountain Bikes | M17: Mountain-200 Silver, 38 | N17: 1 | O17: 1266 | P17: 2320 | Q17: 1054 | R17: =N17*O17 -> 1266 | S17: =N17*P17 -> 2320
A18: 000261711 | B18: 44537 | C18: 7 | D18: Decmber | E18: 2021 | F18: 30 | G18: Young Adults (25-34) | H18: M | I18: United States | J18: California | K18: Bikes | L18: Mountain Bikes | M18: Mountain-400-W Silver, 38 | N18: 4 | O18: 420 | P18: 769 | Q18: 1396 | R18: =N18*O18 -> 1680 | S18: =N18*P18 -> 3076
A19: 000261712 | B19: 44537 | C19: 7 | D19: December | E19: 2021 | F19: 38 | G19: Adults (35-64) | H19: M | I19: United States | J19: California | K19: Bikes | L19: Mountain Bikes | M19: Mountain-200 Silver, 42 | N19: 2 | O19: 1266 | P19: 2320 | Q19: 2108 | R19: =N19*O19 -> 2532 | S19: =N19*P19 -> 4640
A20: 000261713 | B20: 44538 | C20: 8 | D20: December | E20: 2021 | F20: 19 | G20: Youth (<25) | H20: F | I20: Australia | J20: New South Wales | K20: Bikes | L20: Mountain Bikes | M20: Mountain-500 Silver, 42 | N20: 4 | O20: 308 | P20: 565 | Q20: 1028 | R20: =N20*O20 -> 1232 | S20: =N20*P20 -> 2260
A21: 000261714 | B21: 44538 | C21: 8 | D21: December | E21: 2021 | F21: 30 | G21: Young Adults (25-34) | H21: F | I21: Canada | J21: British Columbia | K21: Bikes | L21: Mountain Bikes | M21: Mountain-200 Silver, 38 | N21: 4 | O21: 1266 | P21: 2320 | Q21: 4216 | R21: =N21*O21 -> 5064 | S21: =N21*P21 -> 9280
A22: 000261715 | B22: 44538 | C22: 8 | D22: December | E22: 2021 | F22: 39 | G22: Adults (35-64) | H22: F | I22: United States | J22: Oregon | K22: Bikes | L22: Mountain Bikes | N22: 2 | O22: 1252 | P22: 2295 | Q22: 2086 | R22: =N22*O22 -> 2504 | S22: =N22*P22 -> 4590
A23: 000261716 | B23: 44538 | C23: 8 | D23: December | E23: 2021 | F23: 35 | G23: Adults (35-64) | H23: F | I23: United States | J23: California | K23: Bikes | L23: Mountain Bikes | M23: Mountain-500 Black, 42 | O23: 295 | P23: 540 | Q23: 245 | R23: =N23*O23 -> 0 | S23: =N23*P23 -> 0
A24: 000261717 | B24: 44539 | C24: 9 | D24: December | E24: 2021 | F24: 33 | G24: Young Adults (25-34) | H24: F | I24: Australia | J24: Victoria | K24: Bikes | L24: Mountain Bikes | M24: Mountain-100 Black, 38 | N24: 2 | O24: 1898 | P24: 3375 | Q24: 2954 | R24: =N24*O24 -> 3796 | S24: =N24*P24 -> 6750
A25: 000261718 | B25: 44539 | C25: 9 | D25: December | E25: 2021 | F25: 41 | G25: Adults (35-64) | H25: F | I25: Germany | J25: Hamburg | K25: Bikes | L25: Mountain Bikes | M25: Mountain-200 Silver, 42 | N25: 1 | O25: 1266 | P25: 2320 | Q25: 1054 | R25: =N25*O25 -> 1266 | S25: =N25*P25 -> 2320
A26: 000261719 | B26: 44540 | C26: 10 | D26: December | E26: 2021 | F26: 34 | G26: Young Adults (25-34) | H26: F | I26: United States | J26: California | K26: Bikes | L26: Mountain Bikes | M26: Mountain-200 Black, 42 | N26: 2 | O26: 1252 | P26: 2295 | Q26: 2086 | R26: =N26*O26 -> 2504 | S26: =N26*P26 -> 4590
A27: 000261720 | B27: 44540 | C27: 10 | D27: December | E27: 2021 | F27: 40 | G27: Adults (35-64) | H27: M | I27: Australia | J27: New South Wales | K27: Bikes | L27: Mountain Bikes | M27: Mountain-200 Black, 42 | N27: 2 | O27: 1252 | P27: 2295 | Q27: 2086 | R27: =N27*O27 -> 2504 | S27: =N27*P27 -> 4590
A28: 000261721 | B28: 44540 | C28: 10 | D28: December | E28: 2021 | F28: 26 | G28: Young Adults (25-34) | H28: M | I28: United Kingdom | J28: England | K28: Bikes | L28: Mountain Bikes | M28: Mountain-200 Black, 38 | N28: 1 | O28: 1252 | P28: 2295 | Q28: 1043 | R28: =N28*O28 -> 1252 | S28: =N28*P28 -> 2295
A29: 000261722 | B29: 44540 | C29: 10 | D29: December | E29: 2021 | F29: 34 | G29: Young Adults (25-34) | H29: M | I29: United States | J29: California | K29: Bikes | L29: Mountain Bikes | M29: Mountain-500 Black, 40 | N29: 1 | O29: 295 | P29: 540 | Q29: 245 | R29: =N29*O29 -> 295 | S29: =N29*P29 -> 540
A30: 000261723 | B30: 44540 | C30: 10 | D30: December | E30: 2021 | F30: 34 | G30: Young Adults (25-34) | H30: F | I30: United States | J30: Washington | K30: Bikes | L30: Mountain Bikes | M30: Mountain-100 Silver, 44 | N30: 1 | O30: 1912 | P30: 3400 | Q30: 1488 | R30: =N30*O30 -> 1912 | S30: =N30*P30 -> 3400
A31: 000261724 | B31: 44540 | C31: 10 | D31: December | E31: 2021 | F31: 38 | G31: Adults (35-64) | H31: M | I31: Australia | J31: New South Wales | K31: Bikes | L31: Mountain Bikes | M31: Mountain-200 Black, 38 | N31: 1 | O31: 1252 | P31: 2295 | Q31: 1043 | R31: =N31*O31 -> 1252 | S31: =N31*P31 -> 2295
A32: 000261725 | B32: 44541 | C32: 11 | D32: December | E32: 2021 | F32: 24 | G32: Youth (<25) | H32: F | I32: France | J32: Seine (Paris) | K32: Bikes | L32: Mountain Bikes | M32: Mountain-200 Black, 38 | N32: 3 | O32: 1252 | P32: 2295 | Q32: 3129 | R32: =N32*O32 -> 3756 | S32: =N32*P32 -> 6885
A33: 000261726 | B33: 44541 | C33: 11 | D33: December | E33: 2021 | F33: 41 | G33: Adults (35-64) | H33: F | I33: Australia | J33: New South Wales | K33: Bikes | L33: Mountain Bikes | M33: Mountain-400-W Silver, 38 | N33: 2 | O33: 420 | P33: 769 | Q33: 698 | R33: =N33*O33 -> 840 | S33: =N33*P33 -> 1538
A34: 000261727 | B34: 44541 | C34: 11 | D34: December | E34: 2021 | F34: 27 | G34: Young Adults (25-34) | H34: M | I34: Canada | J34: British Columbia | K34: Bikes | L34: Mountain Bikes | M34: Mountain-200 Black, 46 | N34: 1 | O34: 1252 | P34: 2295 | Q34: 1043 | R34: =N34*O34 -> 1252 | S34: =N34*P34 -> 2295
A35: 000261728 | B35: 44541 | C35: 11 | D35: December | E35: 2021 | F35: 37 | G35: Adults (35-64) | H35: M | I35: United States | J35: California | K35: Bikes | L35: Mountain Bikes | M35: Mountain-400-W Silver, 46 | N35: 1 | O35: 420 | P35: 769 | Q35: 349 | R35: =N35*O35 -> 420 | S35: =N35*P35 -> 769
... A89: 000261782 | B89: 44554 | C89: 24 | D89: December | E89: 2021 | F89: 38 | G89: Adults (35-64) | H89: M | I89: Australia | J89: Queensland | K89: Bikes | L89: Mountain Bikes | M89: Mountain-200 Black, 42 | N89: 4 | O89: 1252 | P89: 2295 | Q89: 4172 | R89: =N89*O89 -> 5008 | S89: =N89*P89 -> 9180

Sheet Clean_Data
A1: Sales_Order # | B1: Date | C1: Day | D1: Month | E1: Year | F1: Customer_Age | G1: Age_Group | H1: Customer_Gender | I1: Country | J1: State | K1: Product_Category | L1: Sub_Category | M1: Product_Description | N1: Model | O1: Size | P1: Order_Quantity | Q1: Unit_Cost | R1: Unit_Price | S1: Cost | T1: Revenue | U1: Profit | V1: Week | W1: Weekday
A2: 261695 | B2: 44531 | C2: 1 | D2: December | E2: 2021 | F2: 39 | G2: Adults (35-64) | H2: F | I2: United States | J2: California | K2: Bikes | L2: Mountain Bikes | M2: Mountain-200 Black, 46 | N2: =IFERROR(LEFT(M2,FIND(",",M2)-1),M2) -> Mountain-200 Black | O2: =IFERROR(TRIM(MID(M2,FIND(",",M2)+1,20)),"") -> 46 | P2: 4 | Q2: 1252 | R2: 2295 | S2: =P2*Q2 -> 5008 | T2: =P2*R2 -> 9180 | U2: =T2-S2 -> 4172 | V2: ="Week "&(INT((C2-1)/7)+1) -> Week 1 | W2: =TEXT(B2,"ddd") -> Wed
A3: 261695 | B3: 44531 | C3: 1 | D3: December | E3: 2021 | F3: 44 | G3: Adults (35-64) | H3: M | I3: United Kingdom | J3: England | K3: Bikes | L3: Mountain Bikes | M3: Mountain-200 Silver, 42 | N3: =IFERROR(LEFT(M3,FIND(",",M3)-1),M3) -> Mountain-200 Silver | O3: =IFERROR(TRIM(MID(M3,FIND(",",M3)+1,20)),"") -> 42 | P3: 1 | Q3: 1266 | R3: 2320 | S3: =P3*Q3 -> 1266 | T3: =P3*R3 -> 2320 | U3: =T3-S3 -> 1054 | V3: ="Week "&(INT((C3-1)/7)+1) -> Week 1 | W3: =TEXT(B3,"ddd") -> Wed
A4: 261697 | B4: 44532 | C4: 2 | D4: December | E4: 2021 | F4: 37 | G4: Adults (35-64) | H4: M | I4: United States | J4: California | K4: Bikes | L4: Mountain Bikes | M4: Mountain-400-W Silver, 46 | N4: =IFERROR(LEFT(M4,FIND(",",M4)-1),M4) -> Mountain-400-W Silver | O4: =IFERROR(TRIM(MID(M4,FIND(",",M4)+1,20)),"") -> 46 | P4: 2 | Q4: 420 | R4: 769 | S4: =P4*Q4 -> 840 | T4: =P4*R4 -> 1538 | U4: =T4-S4 -> 698 | V4: ="Week "&(INT((C4-1)/7)+1) -> Week 1 | W4: =TEXT(B4,"ddd") -> Thu
A5: 261698 | B5: 44532 | C5: 2 | D5: December | E5: 2021 | F5: 31 | G5: Young Adults (25-34) | H5: F | I5: Australia | J5: New South Wales | K5: Bikes | L5: Mountain Bikes | M5: Mountain-400-W Silver, 42 | N5: =IFERROR(LEFT(M5,FIND(",",M5)-1),M5) -> Mountain-400-W Silver | O5: =IFERROR(TRIM(MID(M5,FIND(",",M5)+1,20)),"") -> 42 | P5: 1 | Q5: 420 | R5: 769 | S5: =P5*Q5 -> 420 | T5: =P5*R5 -> 769 | U5: =T5-S5 -> 349 | V5: ="Week "&(INT((C5-1)/7)+1) -> Week 1 | W5: =TEXT(B5,"ddd") -> Thu
A6: 261699 | B6: 44533 | C6: 3 | D6: December | E6: 2021 | F6: 37 | G6: Adults (35-64) | H6: F | I6: United States | J6: California | K6: Bikes | L6: Mountain Bikes | M6: Mountain-200 Black, 46 | N6: =IFERROR(LEFT(M6,FIND(",",M6)-1),M6) -> Mountain-200 Black | O6: =IFERROR(TRIM(MID(M6,FIND(",",M6)+1,20)),"") -> 46 | P6: 2 | Q6: 1252 | R6: 2295 | S6: =P6*Q6 -> 2504 | T6: =P6*R6 -> 4590 | U6: =T6-S6 -> 2086 | V6: ="Week "&(INT((C6-1)/7)+1) -> Week 1 | W6: =TEXT(B6,"ddd") -> Fri
A7: 261700 | B7: 44533 | C7: 3 | D7: December | E7: 2021 | F7: 24 | G7: Youth (<25) | H7: F | I7: United Kingdom | J7: England | K7: Bikes | L7: Mountain Bikes | M7: Mountain-200 Black, 38 | N7: =IFERROR(LEFT(M7,FIND(",",M7)-1),M7) -> Mountain-200 Black | O7: =IFERROR(TRIM(MID(M7,FIND(",",M7)+1,20)),"") -> 38 | P7: 1 | Q7: 1252 | R7: 2295 | S7: =P7*Q7 -> 1252 | T7: =P7*R7 -> 2295 | U7: =T7-S7 -> 1043 | V7: ="Week "&(INT((C7-1)/7)+1) -> Week 1 | W7: =TEXT(B7,"ddd") -> Fri
A8: 261701 | B8: 44533 | C8: 3 | D8: December | E8: 2021 | F8: 37 | G8: Adults (35-64) | H8: M | I8: United States | J8: Washington | K8: Bikes | L8: Mountain Bikes | M8: Mountain-200 Black, 46 | N8: =IFERROR(LEFT(M8,FIND(",",M8)-1),M8) -> Mountain-200 Black | O8: =IFERROR(TRIM(MID(M8,FIND(",",M8)+1,20)),"") -> 46 | P8: 1 | Q8: 1252 | R8: 2295 | S8: =P8*Q8 -> 1252 | T8: =P8*R8 -> 2295 | U8: =T8-S8 -> 1043 | V8: ="Week "&(INT((C8-1)/7)+1) -> Week 1 | W8: =TEXT(B8,"ddd") -> Fri
A9: 261702 | B9: 44534 | C9: 4 | D9: December | E9: 2021 | F9: 31 | G9: Young Adults (25-34) | H9: F | I9: Australia | J9: New South Wales | K9: Bikes | L9: Mountain Bikes | M9: Mountain-400-W Silver, 42 | N9: =IFERROR(LEFT(M9,FIND(",",M9)-1),M9) -> Mountain-400-W Silver | O9: =IFERROR(TRIM(MID(M9,FIND(",",M9)+1,20)),"") -> 42 | P9: 4 | Q9: 420 | R9: 769 | S9: =P9*Q9 -> 1680 | T9: =P9*R9 -> 3076 | U9: =T9-S9 -> 1396 | V9: ="Week "&(INT((C9-1)/7)+1) -> Week 1 | W9: =TEXT(B9,"ddd") -> Sat
A10: 261703 | B10: 44535 | C10: 5 | D10: December | E10: 2021 | F10: 39 | G10: Adults (35-64) | H10: F | I10: United States | J10: California | K10: Bikes | L10: Mountain Bikes | M10: Mountain-200 Black, 46 | N10: =IFERROR(LEFT(M10,FIND(",",M10)-1),M10) -> Mountain-200 Black | O10: =IFERROR(TRIM(MID(M10,FIND(",",M10)+1,20)),"") -> 46 | P10: 4 | Q10: 1252 | R10: 2295 | S10: =P10*Q10 -> 5008 | T10: =P10*R10 -> 9180 | U10: =T10-S10 -> 4172 | V10: ="Week "&(INT((C10-1)/7)+1) -> Week 1 | W10: =TEXT(B10,"ddd") -> Sun
A11: 261704 | B11: 44535 | C11: 5 | D11: December | E11: 2021 | F11: 42 | G11: Adults (35-64) | H11: M | I11: Germany | J11: Nordrhein-Westfalen | K11: Bikes | L11: Mountain Bikes | M11: Mountain-200 Black, 38 | N11: =IFERROR(LEFT(M11,FIND(",",M11)-1),M11) -> Mountain-200 Black | O11: =IFERROR(TRIM(MID(M11,FIND(",",M11)+1,20)),"") -> 38 | P11: 4 | Q11: 1252 | R11: 2295 | S11: =P11*Q11 -> 5008 | T11: =P11*R11 -> 9180 | U11: =T11-S11 -> 4172 | V11: ="Week "&(INT((C11-1)/7)+1) -> Week 1 | W11: =TEXT(B11,"ddd") -> Sun
A12: 261705 | B12: 44535 | C12: 5 | D12: December | E12: 2021 | F12: 35 | G12: Adults (35-64) | H12: F | I12: Australia | J12: Queensland | K12: Bikes | L12: Mountain Bikes | M12: Mountain-200 Silver, 38 | N12: =IFERROR(LEFT(M12,FIND(",",M12)-1),M12) -> Mountain-200 Silver | O12: =IFERROR(TRIM(MID(M12,FIND(",",M12)+1,20)),"") -> 38 | P12: 1 | Q12: 1266 | R12: 2320 | S12: =P12*Q12 -> 1266 | T12: =P12*R12 -> 2320 | U12: =T12-S12 -> 1054 | V12: ="Week "&(INT((C12-1)/7)+1) -> Week 1 | W12: =TEXT(B12,"ddd") -> Sun
A13: 261706 | B13: 44535 | C13: 5 | D13: December | E13: 2021 | F13: 37 | G13: Adults (35-64) | H13: F | I13: United States | J13: California | K13: Bikes | L13: Mountain Bikes | M13: Mountain-200 Black, 46 | N13: =IFERROR(LEFT(M13,FIND(",",M13)-1),M13) -> Mountain-200 Black | O13: =IFERROR(TRIM(MID(M13,FIND(",",M13)+1,20)),"") -> 46 | P13: 1 | Q13: 1252 | R13: 2295 | S13: =P13*Q13 -> 1252 | T13: =P13*R13 -> 2295 | U13: =T13-S13 -> 1043 | V13: ="Week "&(INT((C13-1)/7)+1) -> Week 1 | W13: =TEXT(B13,"ddd") -> Sun
... A89: 261782 | B89: 44554 | C89: 24 | D89: December | E89: 2021 | F89: 38 | G89: Adults (35-64) | H89: M | I89: Australia | J89: Queensland | K89: Bikes | L89: Mountain Bikes | M89: Mountain-200 Black, 42 | N89: =IFERROR(LEFT(M89,FIND(",",M89)-1),M89) -> Mountain-200 Black | O89: =IFERROR(TRIM(MID(M89,FIND(",",M89)+1,20)),"") -> 42 | P89: 4 | Q89: 1252 | R89: 2295 | S89: =P89*Q89 -> 5008 | T89: =P89*R89 -> 9180 | U89: =T89-S89 -> 4172 | V89: ="Week "&(INT((C89-1)/7)+1) -> Week 4 | W89: =TEXT(B89,"ddd") -> Fri
A91: Yellow cells = values corrected during cleaning. Cost, Revenue and Profit are formulas (Qty × Unit Cost / Unit Price).

Sheet Analysis
A1: Analysis – calculation tables behind the dashboard
A3: Country criterion | B3: =IF(Dashboard!$E$4="All","*",Dashboard!$E$4) -> * | J3: Country list | K3: Gender list | L3: Age-group list
A4: Gender criterion | B4: =IF(Dashboard!$I$4="All","*",Dashboard!$I$4) -> * | J4: All | K4: All | L4: All
A5: Age-group criterion | B5: =IF(Dashboard!$M$4="All","*",Dashboard!$M$4) -> * | J5: United States | K5: F | L5: Youth (<25)
J6: Australia | K6: M | L6: Young Adults (25-34)
A7: 1. Headline KPIs | J7: France | L7: Adults (35-64)
A8: Indicator | B8: Value | J8: Germany
A9: Revenue | B9: =SUMIFS(Clean_Data!$T$2:$T$89,Clean_Data!$I$2:$I$89,$B$3,Clean_Data!$H$2:$H$89,$B$4,Clean_Data!$G$2:$G$89,$B$5) -> 361232 | J9: Canada
A10: Cost | B10: =SUMIFS(Clean_Data!$S$2:$S$89,Clean_Data!$I$2:$I$89,$B$3,Clean_Data!$H$2:$H$89,$B$4,Clean_Data!$G$2:$G$89,$B$5) -> 197724 | J10: United Kingdom
A11: Profit | B11: =SUMIFS(Clean_Data!$U$2:$U$89,Clean_Data!$I$2:$I$89,$B$3,Clean_Data!$H$2:$H$89,$B$4,Clean_Data!$G$2:$G$89,$B$5) -> 163508
A12: Profit margin % | B12: =IFERROR(B11/B9,0) -> 0.45263985
A13: Orders (sales lines) | B13: =COUNTIFS(Clean_Data!$I$2:$I$89,$B$3,Clean_Data!$H$2:$H$89,$B$4,Clean_Data!$G$2:$G$89,$B$5) -> 88
A14: Units sold | B14: =SUMIFS(Clean_Data!$P$2:$P$89,Clean_Data!$I$2:$I$89,$B$3,Clean_Data!$H$2:$H$89,$B$4,Clean_Data!$G$2:$G$89,$B$5) -> 187
A15: Average order value | B15: =IFERROR(B9/B13,0) -> 4104.9091
A16: Average customer age | B16: =IFERROR(AVERAGEIFS(Clean_Data!$F$2:$F$89,Clean_Data!$I$2:$I$89,$B$3,Clean_Data!$H$2:$H$89,$B$4,Clean_Data!$G$2:$G$89,$B$5),0) -> 34.170455
A18: 2. Daily trend (1–24 Dec 2021)
A19: Day | B19: Day # | C19: Revenue | D19: Profit | E19: Orders
A20: 01 Dec | B20: 1 | C20: =SUMIFS(Clean_Data!$T$2:$T$89,Clean_Data!$C$2:$C$89,$B20,Clean_Data!$I$2:$I$89,$B$3,Clean_Data!$H$2:$H$89,$B$4,Clean_Data!$G$2:$G$89,$B$5) -> 11500 | D20: =SUMIFS(Clean_Data!$U$2:$U$89,Clean_Data!$C$2:$C$89,$B20,Clean_Data!$I$2:$I$89,$B$3,Clean_Data!$H$2:$H$89,$B$4,Clean_Data!$G$2:$G$89,$B$5) -> 5226 | E20: =COUNTIFS(Clean_Data!$C$2:$C$89,$B20,Clean_Data!$I$2:$I$89,$B$3,Clean_Data!$H$2:$H$89,$B$4,Clean_Data!$G$2:$G$89,$B$5) -> 2
A21: 02 Dec | B21: 2 | C21: =SUMIFS(Clean_Data!$T$2:$T$89,Clean_Data!$C$2:$C$89,$B21,Clean_Data!$I$2:$I$89,$B$3,Clean_Data!$H$2:$H$89,$B$4,Clean_Data!$G$2:$G$89,$B$5) -> 2307 | D21: =SUMIFS(Clean_Data!$U$2:$U$89,Clean_Data!$C$2:$C$89,$B21,Clean_Data!$I$2:$I$89,$B$3,Clean_Data!$H$2:$H$89,$B$4,Clean_Data!$G$2:$G$89,$B$5) -> 1047 | E21: =COUNTIFS(Clean_Data!$C$2:$C$89,$B21,Clean_Data!$I$2:$I$89,$B$3,Clean_Data!$H$2:$H$89,$B$4,Clean_Data!$G$2:$G$89,$B$5) -> 2
A22: 03 Dec | B22: 3 | C22: =SUMIFS(Clean_Data!$T$2:$T$89,Clean_Data!$C$2:$C$89,$B22,Clean_Data!$I$2:$I$89,$B$3,Clean_Data!$H$2:$H$89,$B$4,Clean_Data!$G$2:$G$89,$B$5) -> 9180 | D22: =SUMIFS(Clean_Data!$U$2:$U$89,Clean_Data!$C$2:$C$89,$B22,Clean_Data!$I$2:$I$89,$B$3,Clean_Data!$H$2:$H$89,$B$4,Clean_Data!$G$2:$G$89,$B$5) -> 4172 | E22: =COUNTIFS(Clean_Data!$C$2:$C$89,$B22,Clean_Data!$I$2:$I$89,$B$3,Clean_Data!$H$2:$H$89,$B$4,Clean_Data!$G$2:$G$89,$B$5) -> 3
A23: 04 Dec | B23: 4 | C23: =SUMIFS(Clean_Data!$T$2:$T$89,Clean_Data!$C$2:$C$89,$B23,Clean_Data!$I$2:$I$89,$B$3,Clean_Data!$H$2:$H$89,$B$4,Clean_Data!$G$2:$G$89,$B$5) -> 3076 | D23: =SUMIFS(Clean_Data!$U$2:$U$89,Clean_Data!$C$2:$C$89,$B23,Clean_Data!$I$2:$I$89,$B$3,Clean_Data!$H$2:$H$89,$B$4,Clean_Data!$G$2:$G$89,$B$5) -> 1396 | E23: =COUNTIFS(Clean_Data!$C$2:$C$89,$B23,Clean_Data!$I$2:$I$89,$B$3,Clean_Data!$H$2:$H$89,$B$4,Clean_Data!$G$2:$G$89,$B$5) -> 1
A24: 05 Dec | B24: 5 | C24: =SUMIFS(Clean_Data!$T$2:$T$89,Clean_Data!$C$2:$C$89,$B24,Clean_Data!$I$2:$I$89,$B$3,Clean_Data!$H$2:$H$89,$B$4,Clean_Data!$G$2:$G$89,$B$5) -> 22975 | D24: =SUMIFS(Clean_Data!$U$2:$U$89,Clean_Data!$C$2:$C$89,$B24,Clean_Data!$I$2:$I$89,$B$3,Clean_Data!$H$2:$H$89,$B$4,Clean_Data!$G$2:$G$89,$B$5) -> 10441 | E24: =COUNTIFS(Clean_Data!$C$2:$C$89,$B24,Clean_Data!$I$2:$I$89,$B$3,Clean_Data!$H$2:$H$89,$B$4,Clean_Data!$G$2:$G$89,$B$5) -> 4
A25: 06 Dec | B25: 6 | C25: =SUMIFS(Clean_Data!$T$2:$T$89,Clean_Data!$C$2:$C$89,$B25,Clean_Data!$I$2:$I$89,$B$3,Clean_Data!$H$2:$H$89,$B$4,Clean_Data!$G$2:$G$89,$B$5) -> 9217 | D25: =SUMIFS(Clean_Data!$U$2:$U$89,Clean_Data!$C$2:$C$89,$B25,Clean_Data!$I$2:$I$89,$B$3,Clean_Data!$H$2:$H$89,$B$4,Clean_Data!$G$2:$G$89,$B$5) -> 4187 | E25: =COUNTIFS(Clean_Data!$C$2:$C$89,$B25,Clean_Data!$I$2:$I$89,$B$3,Clean_Data!$H$2:$H$89,$B$4,Clean_Data!$G$2:$G$89,$B$5) -> 4
A26: 07 Dec | B26: 7 | C26: =SUMIFS(Clean_Data!$T$2:$T$89,Clean_Data!$C$2:$C$89,$B26,Clean_Data!$I$2:$I$89,$B$3,Clean_Data!$H$2:$H$89,$B$4,Clean_Data!$G$2:$G$89,$B$5) -> 7716 | D26: =SUMIFS(Clean_Data!$U$2:$U$89,Clean_Data!$C$2:$C$89,$B26,Clean_Data!$I$2:$I$89,$B$3,Clean_Data!$H$2:$H$89,$B$4,Clean_Data!$G$2:$G$89,$B$5) -> 3504 | E26: =COUNTIFS(Clean_Data!$C$2:$C$89,$B26,Clean_Data!$I$2:$I$89,$B$3,Clean_Data!$H$2:$H$89,$B$4,Clean_Data!$G$2:$G$89,$B$5) -> 2
A27: 08 Dec | B27: 8 | C27: =SUMIFS(Clean_Data!$T$2:$T$89,Clean_Data!$C$2:$C$89,$B27,Clean_Data!$I$2:$I$89,$B$3,Clean_Data!$H$2:$H$89,$B$4,Clean_Data!$G$2:$G$89,$B$5) -> 16670 | D27: =SUMIFS(Clean_Data!$U$2:$U$89,Clean_Data!$C$2:$C$89,$B27,Clean_Data!$I$2:$I$89,$B$3,Clean_Data!$H$2:$H$89,$B$4,Clean_Data!$G$2:$G$89,$B$5) -> 7575 | E27: =COUNTIFS(Clean_Data!$C$2:$C$89,$B27,Clean_Data!$I$2:$I$89,$B$3,Clean_Data!$H$2:$H$89,$B$4,Clean_Data!$G$2:$G$89,$B$5) -> 4
A28: 09 Dec | B28: 9 | C28: =SUMIFS(Clean_Data!$T$2:$T$89,Clean_Data!$C$2:$C$89,$B28,Clean_Data!$I$2:$I$89,$B$3,Clean_Data!$H$2:$H$89,$B$4,Clean_Data!$G$2:$G$89,$B$5) -> 9070 | D28: =SUMIFS(Clean_Data!$U$2:$U$89,Clean_Data!$C$2:$C$89,$B28,Clean_Data!$I$2:$I$89,$B$3,Clean_Data!$H$2:$H$89,$B$4,Clean_Data!$G$2:$G$89,$B$5) -> 4008 | E28: =COUNTIFS(Clean_Data!$C$2:$C$89,$B28,Clean_Data!$I$2:$I$89,$B$3,Clean_Data!$H$2:$H$89,$B$4,Clean_Data!$G$2:$G$89,$B$5) -> 2
A29: 10 Dec | B29: 10 | C29: =SUMIFS(Clean_Data!$T$2:$T$89,Clean_Data!$C$2:$C$89,$B29,Clean_Data!$I$2:$I$89,$B$3,Clean_Data!$H$2:$H$89,$B$4,Clean_Data!$G$2:$G$89,$B$5) -> 17710 | D29: =SUMIFS(Clean_Data!$U$2:$U$89,Clean_Data!$C$2:$C$89,$B29,Clean_Data!$I$2:$I$89,$B$3,Clean_Data!$H$2:$H$89,$B$4,Clean_Data!$G$2:$G$89,$B$5) -> 7991 | E29: =COUNTIFS(Clean_Data!$C$2:$C$89,$B29,Clean_Data!$I$2:$I$89,$B$3,Clean_Data!$H$2:$H$89,$B$4,Clean_Data!$G$2:$G$89,$B$5) -> 6
A30: 11 Dec | B30: 11 | C30: =SUMIFS(Clean_Data!$T$2:$T$89,Clean_Data!$C$2:$C$89,$B30,Clean_Data!$I$2:$I$89,$B$3,Clean_Data!$H$2:$H$89,$B$4,Clean_Data!$G$2:$G$89,$B$5) -> 13807 | D30: =SUMIFS(Clean_Data!$U$2:$U$89,Clean_Data!$C$2:$C$89,$B30,Clean_Data!$I$2:$I$89,$B$3,Clean_Data!$H$2:$H$89,$B$4,Clean_Data!$G$2:$G$89,$B$5) -> 6273 | E30: =COUNTIFS(Clean_Data!$C$2:$C$89,$B30,Clean_Data!$I$2:$I$89,$B$3,Clean_Data!$H$2:$H$89,$B$4,Clean_Data!$G$2:$G$89,$B$5) -> 5
A31: 12 Dec | B31: 12 | C31: =SUMIFS(Clean_Data!$T$2:$T$89,Clean_Data!$C$2:$C$89,$B31,Clean_Data!$I$2:$I$89,$B$3,Clean_Data!$H$2:$H$89,$B$4,Clean_Data!$G$2:$G$89,$B$5) -> 21586 | D31: =SUMIFS(Clean_Data!$U$2:$U$89,Clean_Data!$C$2:$C$89,$B31,Clean_Data!$I$2:$I$89,$B$3,Clean_Data!$H$2:$H$89,$B$4,Clean_Data!$G$2:$G$89,$B$5) -> 9806 | E31: =COUNTIFS(Clean_Data!$C$2:$C$89,$B31,Clean_Data!$I$2:$I$89,$B$3,Clean_Data!$H$2:$H$89,$B$4,Clean_Data!$G$2:$G$89,$B$5) -> 5
... A43: 24 Dec | B43: 24 | C43: =SUMIFS(Clean_Data!$T$2:$T$89,Clean_Data!$C$2:$C$89,$B43,Clean_Data!$I$2:$I$89,$B$3,Clean_Data!$H$2:$H$89,$B$4,Clean_Data!$G$2:$G$89,$B$5) -> 9180 | D43: =SUMIFS(Clean_Data!$U$2:$U$89,Clean_Data!$C$2:$C$89,$B43,Clean_Data!$I$2:$I$89,$B$3,Clean_Data!$H$2:$H$89,$B$4,Clean_Data!$G$2:$G$89,$B$5) -> 4172 | E43: =COUNTIFS(Clean_Data!$C$2:$C$89,$B43,Clean_Data!$I$2:$I$89,$B$3,Clean_Data!$H$2:$H$89,$B$4,Clean_Data!$G$2:$G$89,$B$5) -> 1
A46: 3. Country (ignores the Country filter)
A47: Country | B47: Revenue | C47: Profit | D47: Margin % | E47: Units | F47: Orders | G47: Share of revenue
A48: United States | B48: =SUMIFS(Clean_Data!$T$2:$T$89,Clean_Data!$I$2:$I$89,$A48,Clean_Data!$H$2:$H$89,$B$4,Clean_Data!$G$2:$G$89,$B$5) -> 133489 | C48: =SUMIFS(Clean_Data!$U$2:$U$89,Clean_Data!$I$2:$I$89,$A48,Clean_Data!$H$2:$H$89,$B$4,Clean_Data!$G$2:$G$89,$B$5) -> 60370 | D48: =IFERROR(C48/B48,0) -> 0.452247 | E48: =SUMIFS(Clean_Data!$P$2:$P$89,Clean_Data!$I$2:$I$89,$A48,Clean_Data!$H$2:$H$89,$B$4,Clean_Data!$G$2:$G$89,$B$5) -> 66 | F48: =COUNTIFS(Clean_Data!$I$2:$I$89,$A48,Clean_Data!$H$2:$H$89,$B$4,Clean_Data!$G$2:$G$89,$B$5) -> 32 | G48: =IFERROR(B48/B$54,0) -> 0.36953814
A49: Australia | B49: =SUMIFS(Clean_Data!$T$2:$T$89,Clean_Data!$I$2:$I$89,$A49,Clean_Data!$H$2:$H$89,$B$4,Clean_Data!$G$2:$G$89,$B$5) -> 111506 | C49: =SUMIFS(Clean_Data!$U$2:$U$89,Clean_Data!$I$2:$I$89,$A49,Clean_Data!$H$2:$H$89,$B$4,Clean_Data!$G$2:$G$89,$B$5) -> 50326 | D49: =IFERROR(C49/B49,0) -> 0.45132997 | E49: =SUMIFS(Clean_Data!$P$2:$P$89,Clean_Data!$I$2:$I$89,$A49,Clean_Data!$H$2:$H$89,$B$4,Clean_Data!$G$2:$G$89,$B$5) -> 63 | F49: =COUNTIFS(Clean_Data!$I$2:$I$89,$A49,Clean_Data!$H$2:$H$89,$B$4,Clean_Data!$G$2:$G$89,$B$5) -> 27 | G49: =IFERROR(B49/B$54,0) -> 0.30868251
A50: France | B50: =SUMIFS(Clean_Data!$T$2:$T$89,Clean_Data!$I$2:$I$89,$A50,Clean_Data!$H$2:$H$89,$B$4,Clean_Data!$G$2:$G$89,$B$5) -> 46175 | C50: =SUMIFS(Clean_Data!$U$2:$U$89,Clean_Data!$I$2:$I$89,$A50,Clean_Data!$H$2:$H$89,$B$4,Clean_Data!$G$2:$G$89,$B$5) -> 20981 | D50: =IFERROR(C50/B50,0) -> 0.45438008 | E50: =SUMIFS(Clean_Data!$P$2:$P$89,Clean_Data!$I$2:$I$89,$A50,Clean_Data!$H$2:$H$89,$B$4,Clean_Data!$G$2:$G$89,$B$5) -> 20 | F50: =COUNTIFS(Clean_Data!$I$2:$I$89,$A50,Clean_Data!$H$2:$H$89,$B$4,Clean_Data!$G$2:$G$89,$B$5) -> 8 | G50: =IFERROR(B50/B$54,0) -> 0.12782644
A51: Germany | B51: =SUMIFS(Clean_Data!$T$2:$T$89,Clean_Data!$I$2:$I$89,$A51,Clean_Data!$H$2:$H$89,$B$4,Clean_Data!$G$2:$G$89,$B$5) -> 30010 | C51: =SUMIFS(Clean_Data!$U$2:$U$89,Clean_Data!$I$2:$I$89,$A51,Clean_Data!$H$2:$H$89,$B$4,Clean_Data!$G$2:$G$89,$B$5) -> 13636 | D51: =IFERROR(C51/B51,0) -> 0.45438187 | E51: =SUMIFS(Clean_Data!$P$2:$P$89,Clean_Data!$I$2:$I$89,$A51,Clean_Data!$H$2:$H$89,$B$4,Clean_Data!$G$2:$G$89,$B$5) -> 13 | F51: =COUNTIFS(Clean_Data!$I$2:$I$89,$A51,Clean_Data!$H$2:$H$89,$B$4,Clean_Data!$G$2:$G$89,$B$5) -> 6 | G51: =IFERROR(B51/B$54,0) -> 0.083076804
A52: Canada | B52: =SUMIFS(Clean_Data!$T$2:$T$89,Clean_Data!$I$2:$I$89,$A52,Clean_Data!$H$2:$H$89,$B$4,Clean_Data!$G$2:$G$89,$B$5) -> 20080 | C52: =SUMIFS(Clean_Data!$U$2:$U$89,Clean_Data!$I$2:$I$89,$A52,Clean_Data!$H$2:$H$89,$B$4,Clean_Data!$G$2:$G$89,$B$5) -> 9123 | D52: =IFERROR(C52/B52,0) -> 0.45433267 | E52: =SUMIFS(Clean_Data!$P$2:$P$89,Clean_Data!$I$2:$I$89,$A52,Clean_Data!$H$2:$H$89,$B$4,Clean_Data!$G$2:$G$89,$B$5) -> 11 | F52: =COUNTIFS(Clean_Data!$I$2:$I$89,$A52,Clean_Data!$H$2:$H$89,$B$4,Clean_Data!$G$2:$G$89,$B$5) -> 6 | G52: =IFERROR(B52/B$54,0) -> 0.055587545
A53: United Kingdom | B53: =SUMIFS(Clean_Data!$T$2:$T$89,Clean_Data!$I$2:$I$89,$A53,Clean_Data!$H$2:$H$89,$B$4,Clean_Data!$G$2:$G$89,$B$5) -> 19972 | C53: =SUMIFS(Clean_Data!$U$2:$U$89,Clean_Data!$I$2:$I$89,$A53,Clean_Data!$H$2:$H$89,$B$4,Clean_Data!$G$2:$G$89,$B$5) -> 9072 | D53: =IFERROR(C53/B53,0) -> 0.45423593 | E53: =SUMIFS(Clean_Data!$P$2:$P$89,Clean_Data!$I$2:$I$89,$A53,Clean_Data!$H$2:$H$89,$B$4,Clean_Data!$G$2:$G$89,$B$5) -> 14 | F53: =COUNTIFS(Clean_Data!$I$2:$I$89,$A53,Clean_Data!$H$2:$H$89,$B$4,Clean_Data!$G$2:$G$89,$B$5) -> 9 | G53: =IFERROR(B53/B$54,0) -> 0.055288568
A54: Total | B54: =SUM(B48:B53) -> 361232 | C54: =SUM(C48:C53) -> 163508 | D54: =IFERROR(C54/B54,0) -> 0.45263985 | E54: =SUM(E48:E53) -> 187 | F54: =SUM(F48:F53) -> 88 | G54: =SUM(G48:G53) -> 1
A57: 4. Product model
...

Sheet Dashboard
A1: BIKE SALES DASHBOARD | Mountain Bikes | 1–24 December 2021 | Favour Daniel, Data Analyst
D4: Country ▸ | E4: All | H4: Gender ▸ | I4: All | L4: Age group ▸ | M4: All
C6: REVENUE | E6: PROFIT | G6: PROFIT MARGIN | I6: ORDERS | K6: UNITS SOLD | M6: AVG ORDER VALUE | O6: AVG CUSTOMER AGE
C7: =Analysis!B9 -> 361232 | E7: =Analysis!B11 -> 163508 | G7: =Analysis!B12 -> 0.45263985 | I7: =Analysis!B13 -> 88 | K7: =Analysis!B14 -> 187 | M7: =Analysis!B15 -> 4104.9091 | O7: =Analysis!B16 -> 34.170455
B10: KEY INSIGHTS (live)
B11: ="Top country: "&INDEX(Analysis!$A$48:$A$53,MATCH(MAX(Analysis!$B$48:$B$53),Analysis!$B$48:$B$53,0))&" ("&TEXT(MAX(Analysis!$G$48:$G$53),"0%")&" of revenue)" -> Top country: United States (37% of revenue)
B13: ="Top model: "&INDEX(Analysis!$A$59:$A$65,MATCH(MAX(Analysis!$B$59:$B$65),Analysis!$B$59:$B$65,0))&" ("&TEXT(MAX(Analysis!$G$59:$G$65),"0%")&" of revenue)" -> Top model: Mountain-200 Black (48% of revenue)
B15: ="Highest-margin model: "&INDEX(Analysis!$A$59:$A$65,MATCH(MAX(Analysis!$D$59:$D$65),Analysis!$D$59:$D$65,0))&" ("&TEXT(MAX(Analysis!$D$59:$D$65),"0.0%")&")" -> Highest-margin model: Mountain-500 Silver (45.5%)
B17: ="Top age group: "&INDEX(Analysis!$A$76:$A$78,MATCH(MAX(Analysis!$B$76:$B$78),Analysis!$B$76:$B$78,0))&" ("&TEXT(MAX(Analysis!$G$76:$G$78),"0%")&")" -> Top age group: Adults (35-64) (57%)
B19: ="Best day: "&INDEX(Analysis!$A$20:$A$43,MATCH(MAX(Analysis!$C$20:$C$43),Analysis!$C$20:$C$43,0))&" ("&TEXT(MAX(Analysis!$C$20:$C$43),"$#,##0")&")" -> Best day: 19 Dec ($69,650)
B21: ="Average daily revenue: "&TEXT(Analysis!$B$9/24,"$#,##0") -> Average daily revenue: $15,051

Sheet Indicators
A1: Possible indicators for this dataset
A3: Category | B3: Indicator | C3: How to calculate | D3: Suggested visual | E3: In sample dashboard?
A4: Sales performance | B4: Total revenue | C4: SUM(Revenue) | D4: KPI card | E4: Yes
A5: Sales performance | B5: Total cost | C5: SUM(Cost) | D5: KPI card / table | E5: Analysis
A6: Sales performance | B6: Total profit | C6: SUM(Profit) | D6: KPI card | E6: Yes
A7: Sales performance | B7: Profit margin % | C7: Profit ÷ Revenue | D7: KPI card, bar by product | E7: Yes
A8: Sales performance | B8: Orders (sales lines) | C8: COUNTA(Sales_Order #) | D8: KPI card | E8: Yes
A9: Sales performance | B9: Units sold | C9: SUM(Order_Quantity) | D9: KPI card | E9: Yes
A10: Sales performance | B10: Average order value | C10: Revenue ÷ Orders | D10: KPI card | E10: Yes
A11: Sales performance | B11: Average profit per unit | C11: Profit ÷ Units | D11: KPI card | E11: Extension
A12: Sales performance | B12: Order size mix (1, 2, 3, 4 units) | C12: COUNTIFS on Order_Quantity | D12: Column chart | E12: Extension
A13: Time trend | B13: Daily revenue & profit | C13: SUMIFS by Day | D13: Line chart | E13: Yes
A14: Time trend | B14: Cumulative revenue | C14: Running SUM of daily revenue | D14: Area / line chart | E14: Extension
... A32: Data quality | B32: % of rows corrected during cleaning | C32: Fixed rows ÷ total rows | D32: Small KPI | E32: Data_Notes
A34: Limits of this dataset
A35: • Only 24 days of one month (Dec 2021): no month-on-month or year-on-year comparison.
A36: • Only one category (Bikes › Mountain Bikes): no category or sub-category comparison.
A37: • No discount, return or customer-ID fields: no discount analysis, repeat-customer or retention metrics.
A38: • Add more months / categories later and every table updates by extending the ranges.

Sheet Data_Notes
A1: Data cleaning log & assumptions
A3: Original row | B3: Column | C3: Issue found | D3: Fix applied
A4: 4 | B4: Country | C4: Extra spaces: " United States" | D4: Trimmed to "United States"
A5: 6 | B5: Country | C5: Extra spaces: "United States" | D5: Trimmed to "United States"
A6: 6 | B6: Unit_Cost | C6: Unit cost = 0 (Cost and Profit were inconsistent) | D6: Replaced with 1,252, the cost of the same product elsewhere
A7: 8 | B7: Country | C7: Extra spaces: "United States " | D7: Trimmed to "United States"
A8: 9 | B8: Unit_Price | C8: Unit price = 0 (Revenue was 0 but Profit was positive) | D8: Replaced with 769, the price of the same product elsewhere
A9: 11 | B9: Day | C9: Blank | D9: Filled from Date column
A10: 16 | B10: Age_Group | C10: Blank | D10: Derived from Customer_Age (36) → Adults (35-64)
A11: 18 | B11: Month | C11: Typo "Decmber" | D11: Corrected to "December"
A12: 22 | B12: Product_Description | C12: Blank | D12: Model inferred from unit cost/price → "Mountain-200 Black"; size unknown
A13: 23 | B13: Order_Quantity | C13: Blank (Cost and Revenue were 0) | D13: Set to 1, implied by the recorded Profit ÷ unit margin
A15: Other notes
A16: • Original rows 90–93 (3 blank rows + a stray line "BDFG61 / 389 / 61 / HRDF / 61") were excluded.
A17: • Stray text "Bikes California" in original cell V4 was ignored.
A18: • Sales_Order # 261695 appears twice for two different customers; each line is treated as a separate order.
A19: • Cost, Revenue and Profit were rebuilt as formulas (Qty × Unit Cost / Unit Price); they match the original on every row not listed above.
A20: • Currency is not stated in the source file; USD is assumed.
